2014-08-13 21:43:59,246 INFO org.apache.hadoop.yarn.server.resourcemanager.ResourceManager: STARTUP_MSG: 
/************************************************************
STARTUP_MSG: Starting ResourceManager
STARTUP_MSG:   host = rticdev.igatecorp.com/172.16.1.31
STARTUP_MSG:   args = []
STARTUP_MSG:   version = 2.4.0
STARTUP_MSG:   build = Unknown -r Unknown; compiled by 'hduser' on 2014-06-05T11:04Z
STARTUP_MSG:   java = 1.7.0_65
************************************************************/
2014-08-13 21:43:59,253 INFO org.apache.hadoop.yarn.server.resourcemanager.ResourceManager: registered UNIX signal handlers for [TERM, HUP, INT]
2014-08-13 21:43:59,428 INFO org.apache.hadoop.conf.Configuration: found resource core-site.xml at file:/usr/local/hadoop-2.4.0/etc/hadoop/core-site.xml
2014-08-13 21:43:59,526 INFO org.apache.hadoop.security.Groups: clearing userToGroupsMap cache
2014-08-13 21:43:59,532 INFO org.apache.hadoop.conf.Configuration: found resource yarn-site.xml at file:/usr/local/hadoop-2.4.0/etc/hadoop/yarn-site.xml
2014-08-13 21:43:59,597 INFO org.apache.hadoop.yarn.event.AsyncDispatcher: Registering class org.apache.hadoop.yarn.server.resourcemanager.RMFatalEventType for class org.apache.hadoop.yarn.server.resourcemanager.ResourceManager$RMFatalEventDispatcher
2014-08-13 21:43:59,703 INFO org.apache.hadoop.yarn.server.resourcemanager.security.NMTokenSecretManagerInRM: NMTokenKeyRollingInterval: 86400000ms and NMTokenKeyActivationDelay: 900000ms
2014-08-13 21:43:59,707 INFO org.apache.hadoop.yarn.server.resourcemanager.security.RMContainerTokenSecretManager: ContainerTokenKeyRollingInterval: 86400000ms and ContainerTokenKeyActivationDelay: 900000ms
2014-08-13 21:43:59,711 INFO org.apache.hadoop.yarn.server.resourcemanager.security.AMRMTokenSecretManager: Rolling master-key for amrm-tokens
2014-08-13 21:43:59,738 INFO org.apache.hadoop.yarn.event.AsyncDispatcher: Registering class org.apache.hadoop.yarn.server.resourcemanager.recovery.RMStateStoreEventType for class org.apache.hadoop.yarn.server.resourcemanager.recovery.RMStateStore$ForwardingEventHandler
2014-08-13 21:43:59,883 INFO org.apache.hadoop.yarn.event.AsyncDispatcher: Registering class org.apache.hadoop.yarn.server.resourcemanager.NodesListManagerEventType for class org.apache.hadoop.yarn.server.resourcemanager.NodesListManager
2014-08-13 21:43:59,883 INFO org.apache.hadoop.yarn.server.resourcemanager.ResourceManager: Using Scheduler: org.apache.hadoop.yarn.server.resourcemanager.scheduler.capacity.CapacityScheduler
2014-08-13 21:43:59,921 INFO org.apache.hadoop.yarn.event.AsyncDispatcher: Registering class org.apache.hadoop.yarn.server.resourcemanager.scheduler.event.SchedulerEventType for class org.apache.hadoop.yarn.server.resourcemanager.ResourceManager$SchedulerEventDispatcher
2014-08-13 21:43:59,922 INFO org.apache.hadoop.yarn.event.AsyncDispatcher: Registering class org.apache.hadoop.yarn.server.resourcemanager.rmapp.RMAppEventType for class org.apache.hadoop.yarn.server.resourcemanager.ResourceManager$ApplicationEventDispatcher
2014-08-13 21:43:59,923 INFO org.apache.hadoop.yarn.event.AsyncDispatcher: Registering class org.apache.hadoop.yarn.server.resourcemanager.rmapp.attempt.RMAppAttemptEventType for class org.apache.hadoop.yarn.server.resourcemanager.ResourceManager$ApplicationAttemptEventDispatcher
2014-08-13 21:43:59,923 INFO org.apache.hadoop.yarn.event.AsyncDispatcher: Registering class org.apache.hadoop.yarn.server.resourcemanager.rmnode.RMNodeEventType for class org.apache.hadoop.yarn.server.resourcemanager.ResourceManager$NodeEventDispatcher
2014-08-13 21:44:00,006 INFO org.apache.hadoop.metrics2.impl.MetricsConfig: loaded properties from hadoop-metrics2.properties
2014-08-13 21:44:00,061 INFO org.apache.hadoop.metrics2.impl.MetricsSystemImpl: Scheduled snapshot period at 10 second(s).
2014-08-13 21:44:00,061 INFO org.apache.hadoop.metrics2.impl.MetricsSystemImpl: ResourceManager metrics system started
2014-08-13 21:44:00,068 INFO org.apache.hadoop.conf.Configuration: found resource capacity-scheduler.xml at file:/usr/local/hadoop-2.4.0/etc/hadoop/capacity-scheduler.xml
2014-08-13 21:44:00,133 INFO org.apache.hadoop.yarn.server.resourcemanager.scheduler.capacity.ParentQueue: root, capacity=1.0, asboluteCapacity=1.0, maxCapacity=1.0, asboluteMaxCapacity=1.0, state=RUNNING, acls=SUBMIT_APPLICATIONS:*ADMINISTER_QUEUE:*
2014-08-13 21:44:00,133 INFO org.apache.hadoop.yarn.server.resourcemanager.scheduler.capacity.ParentQueue: Initialized parent-queue root name=root, fullname=root
2014-08-13 21:44:00,140 INFO org.apache.hadoop.yarn.server.resourcemanager.scheduler.capacity.LeafQueue: Initializing default
capacity = 1.0 [= (float) configuredCapacity / 100 ]
asboluteCapacity = 1.0 [= parentAbsoluteCapacity * capacity ]
maxCapacity = 1.0 [= configuredMaxCapacity ]
absoluteMaxCapacity = 1.0 [= 1.0 maximumCapacity undefined, (parentAbsoluteMaxCapacity * maximumCapacity) / 100 otherwise ]
userLimit = 100 [= configuredUserLimit ]
userLimitFactor = 1.0 [= configuredUserLimitFactor ]
maxApplications = 10000 [= configuredMaximumSystemApplicationsPerQueue or (int)(configuredMaximumSystemApplications * absoluteCapacity)]
maxApplicationsPerUser = 10000 [= (int)(maxApplications * (userLimit / 100.0f) * userLimitFactor) ]
maxActiveApplications = 1 [= max((int)ceil((clusterResourceMemory / minimumAllocation) * maxAMResourcePerQueuePercent * absoluteMaxCapacity),1) ]
maxActiveAppsUsingAbsCap = 1 [= max((int)ceil((clusterResourceMemory / minimumAllocation) *maxAMResourcePercent * absoluteCapacity),1) ]
maxActiveApplicationsPerUser = 1 [= max((int)(maxActiveApplications * (userLimit / 100.0f) * userLimitFactor),1) ]
usedCapacity = 0.0 [= usedResourcesMemory / (clusterResourceMemory * absoluteCapacity)]
absoluteUsedCapacity = 0.0 [= usedResourcesMemory / clusterResourceMemory]
maxAMResourcePerQueuePercent = 0.1 [= configuredMaximumAMResourcePercent ]
minimumAllocationFactor = 0.875 [= (float)(maximumAllocationMemory - minimumAllocationMemory) / maximumAllocationMemory ]
numContainers = 0 [= currentNumContainers ]
state = RUNNING [= configuredState ]
acls = SUBMIT_APPLICATIONS:*ADMINISTER_QUEUE:* [= configuredAcls ]
nodeLocalityDelay = 40

2014-08-13 21:44:00,140 INFO org.apache.hadoop.yarn.server.resourcemanager.scheduler.capacity.CapacityScheduler: Initialized queue: default: capacity=1.0, absoluteCapacity=1.0, usedResources=<memory:0, vCores:0>usedCapacity=0.0, absoluteUsedCapacity=0.0, numApps=0, numContainers=0
2014-08-13 21:44:00,140 INFO org.apache.hadoop.yarn.server.resourcemanager.scheduler.capacity.CapacityScheduler: Initialized queue: root: numChildQueue= 1, capacity=1.0, absoluteCapacity=1.0, usedResources=<memory:0, vCores:0>usedCapacity=0.0, numApps=0, numContainers=0
2014-08-13 21:44:00,140 INFO org.apache.hadoop.yarn.server.resourcemanager.scheduler.capacity.CapacityScheduler: Initialized root queue root: numChildQueue= 1, capacity=1.0, absoluteCapacity=1.0, usedResources=<memory:0, vCores:0>usedCapacity=0.0, numApps=0, numContainers=0
2014-08-13 21:44:00,141 INFO org.apache.hadoop.yarn.server.resourcemanager.scheduler.capacity.CapacityScheduler: Initialized CapacityScheduler with calculator=class org.apache.hadoop.yarn.util.resource.DefaultResourceCalculator, minimumAllocation=<<memory:1024, vCores:1>>, maximumAllocation=<<memory:8192, vCores:32>>, asynchronousScheduling=false, asyncScheduleInterval=5ms
2014-08-13 21:44:00,204 INFO org.apache.hadoop.yarn.event.AsyncDispatcher: Registering class org.apache.hadoop.yarn.server.resourcemanager.RMAppManagerEventType for class org.apache.hadoop.yarn.server.resourcemanager.RMAppManager
2014-08-13 21:44:00,219 INFO org.apache.hadoop.yarn.event.AsyncDispatcher: Registering class org.apache.hadoop.yarn.server.resourcemanager.amlauncher.AMLauncherEventType for class org.apache.hadoop.yarn.server.resourcemanager.amlauncher.ApplicationMasterLauncher
2014-08-13 21:44:00,220 INFO org.apache.hadoop.yarn.server.resourcemanager.RMNMInfo: Registered RMNMInfo MBean
2014-08-13 21:44:00,222 INFO org.apache.hadoop.yarn.event.AsyncDispatcher: Registering class org.apache.hadoop.yarn.server.resourcemanager.ahs.WritingHistoryEventType for class org.apache.hadoop.yarn.server.resourcemanager.ahs.RMApplicationHistoryWriter$ForwardingEventHandler
2014-08-13 21:44:00,222 INFO org.apache.hadoop.yarn.event.AsyncDispatcher: Registering class org.apache.hadoop.yarn.server.resourcemanager.ahs.WritingHistoryEventType for class org.apache.hadoop.yarn.server.resourcemanager.ahs.RMApplicationHistoryWriter$ForwardingEventHandler
2014-08-13 21:44:00,222 INFO org.apache.hadoop.yarn.event.AsyncDispatcher: Registering class org.apache.hadoop.yarn.server.resourcemanager.ahs.WritingHistoryEventType for class org.apache.hadoop.yarn.server.resourcemanager.ahs.RMApplicationHistoryWriter$ForwardingEventHandler
2014-08-13 21:44:00,222 INFO org.apache.hadoop.yarn.event.AsyncDispatcher: Registering class org.apache.hadoop.yarn.server.resourcemanager.ahs.WritingHistoryEventType for class org.apache.hadoop.yarn.server.resourcemanager.ahs.RMApplicationHistoryWriter$ForwardingEventHandler
2014-08-13 21:44:00,222 INFO org.apache.hadoop.yarn.event.AsyncDispatcher: Registering class org.apache.hadoop.yarn.server.resourcemanager.ahs.WritingHistoryEventType for class org.apache.hadoop.yarn.server.resourcemanager.ahs.RMApplicationHistoryWriter$ForwardingEventHandler
2014-08-13 21:44:00,222 INFO org.apache.hadoop.yarn.event.AsyncDispatcher: Registering class org.apache.hadoop.yarn.server.resourcemanager.ahs.WritingHistoryEventType for class org.apache.hadoop.yarn.server.resourcemanager.ahs.RMApplicationHistoryWriter$ForwardingEventHandler
2014-08-13 21:44:00,222 INFO org.apache.hadoop.yarn.event.AsyncDispatcher: Registering class org.apache.hadoop.yarn.server.resourcemanager.ahs.WritingHistoryEventType for class org.apache.hadoop.yarn.server.resourcemanager.ahs.RMApplicationHistoryWriter$ForwardingEventHandler
2014-08-13 21:44:00,222 INFO org.apache.hadoop.yarn.event.AsyncDispatcher: Registering class org.apache.hadoop.yarn.server.resourcemanager.ahs.WritingHistoryEventType for class org.apache.hadoop.yarn.server.resourcemanager.ahs.RMApplicationHistoryWriter$ForwardingEventHandler
2014-08-13 21:44:00,222 INFO org.apache.hadoop.yarn.event.AsyncDispatcher: Registering class org.apache.hadoop.yarn.server.resourcemanager.ahs.WritingHistoryEventType for class org.apache.hadoop.yarn.server.resourcemanager.ahs.RMApplicationHistoryWriter$ForwardingEventHandler
2014-08-13 21:44:00,222 INFO org.apache.hadoop.yarn.event.AsyncDispatcher: Registering class org.apache.hadoop.yarn.server.resourcemanager.ahs.WritingHistoryEventType for class org.apache.hadoop.yarn.server.resourcemanager.ahs.RMApplicationHistoryWriter$ForwardingEventHandler
2014-08-13 21:44:00,223 INFO org.apache.hadoop.util.HostsFileReader: Refreshing hosts (include/exclude) list
2014-08-13 21:44:00,235 INFO org.apache.hadoop.yarn.server.resourcemanager.ResourceManager: Transitioning to active state
2014-08-13 21:44:00,257 INFO org.apache.hadoop.yarn.server.resourcemanager.security.RMContainerTokenSecretManager: Rolling master-key for container-tokens
2014-08-13 21:44:00,257 INFO org.apache.hadoop.yarn.server.resourcemanager.security.AMRMTokenSecretManager: Rolling master-key for amrm-tokens
2014-08-13 21:44:00,259 INFO org.apache.hadoop.yarn.server.resourcemanager.security.NMTokenSecretManagerInRM: Rolling master-key for nm-tokens
2014-08-13 21:44:00,259 INFO org.apache.hadoop.security.token.delegation.AbstractDelegationTokenSecretManager: Updating the current master key for generating delegation tokens
2014-08-13 21:44:00,259 INFO org.apache.hadoop.yarn.server.resourcemanager.security.RMDelegationTokenSecretManager: storing master key with keyID 1
2014-08-13 21:44:00,260 INFO org.apache.hadoop.security.token.delegation.AbstractDelegationTokenSecretManager: Starting expired delegation token remover thread, tokenRemoverScanInterval=60 min(s)
2014-08-13 21:44:00,260 INFO org.apache.hadoop.security.token.delegation.AbstractDelegationTokenSecretManager: Updating the current master key for generating delegation tokens
2014-08-13 21:44:00,260 INFO org.apache.hadoop.yarn.server.resourcemanager.security.RMDelegationTokenSecretManager: storing master key with keyID 2
2014-08-13 21:44:00,297 INFO org.apache.hadoop.ipc.CallQueueManager: Using callQueue class java.util.concurrent.LinkedBlockingQueue
2014-08-13 21:44:00,305 INFO org.apache.hadoop.ipc.Server: Starting Socket Reader #1 for port 8031
2014-08-13 21:44:00,319 INFO org.apache.hadoop.yarn.factories.impl.pb.RpcServerFactoryPBImpl: Adding protocol org.apache.hadoop.yarn.server.api.ResourceTrackerPB to the server
2014-08-13 21:44:00,319 INFO org.apache.hadoop.ipc.Server: IPC Server Responder: starting
2014-08-13 21:44:00,320 INFO org.apache.hadoop.ipc.Server: IPC Server listener on 8031: starting
2014-08-13 21:44:00,356 INFO org.apache.hadoop.ipc.CallQueueManager: Using callQueue class java.util.concurrent.LinkedBlockingQueue
2014-08-13 21:44:00,364 INFO org.apache.hadoop.ipc.Server: Starting Socket Reader #1 for port 8030
2014-08-13 21:44:00,371 INFO org.apache.hadoop.yarn.factories.impl.pb.RpcServerFactoryPBImpl: Adding protocol org.apache.hadoop.yarn.api.ApplicationMasterProtocolPB to the server
2014-08-13 21:44:00,372 INFO org.apache.hadoop.ipc.Server: IPC Server Responder: starting
2014-08-13 21:44:00,372 INFO org.apache.hadoop.ipc.Server: IPC Server listener on 8030: starting
2014-08-13 21:44:00,424 INFO org.apache.hadoop.ipc.CallQueueManager: Using callQueue class java.util.concurrent.LinkedBlockingQueue
2014-08-13 21:44:00,425 INFO org.apache.hadoop.ipc.Server: Starting Socket Reader #1 for port 8032
2014-08-13 21:44:00,430 INFO org.apache.hadoop.yarn.factories.impl.pb.RpcServerFactoryPBImpl: Adding protocol org.apache.hadoop.yarn.api.ApplicationClientProtocolPB to the server
2014-08-13 21:44:00,431 INFO org.apache.hadoop.ipc.Server: IPC Server Responder: starting
2014-08-13 21:44:00,431 INFO org.apache.hadoop.ipc.Server: IPC Server listener on 8032: starting
2014-08-13 21:44:00,436 INFO org.apache.hadoop.yarn.server.resourcemanager.ResourceManager: Transitioned to active state
2014-08-13 21:44:00,487 INFO org.mortbay.log: Logging to org.slf4j.impl.Log4jLoggerAdapter(org.mortbay.log) via org.mortbay.log.Slf4jLog
2014-08-13 21:44:00,489 INFO org.apache.hadoop.http.HttpRequestLog: Http request log for http.requests.resourcemanager is not defined
2014-08-13 21:44:00,497 INFO org.apache.hadoop.http.HttpServer2: Added global filter 'safety' (class=org.apache.hadoop.http.HttpServer2$QuotingInputFilter)
2014-08-13 21:44:00,499 INFO org.apache.hadoop.http.HttpServer2: Added filter static_user_filter (class=org.apache.hadoop.http.lib.StaticUserWebFilter$StaticUserFilter) to context cluster
2014-08-13 21:44:00,499 INFO org.apache.hadoop.http.HttpServer2: Added filter static_user_filter (class=org.apache.hadoop.http.lib.StaticUserWebFilter$StaticUserFilter) to context static
2014-08-13 21:44:00,499 INFO org.apache.hadoop.http.HttpServer2: Added filter static_user_filter (class=org.apache.hadoop.http.lib.StaticUserWebFilter$StaticUserFilter) to context logs
2014-08-13 21:44:00,501 INFO org.apache.hadoop.http.HttpServer2: adding path spec: /cluster/*
2014-08-13 21:44:00,501 INFO org.apache.hadoop.http.HttpServer2: adding path spec: /ws/*
2014-08-13 21:44:00,510 INFO org.apache.hadoop.http.HttpServer2: Jetty bound to port 8088
2014-08-13 21:44:00,510 INFO org.mortbay.log: jetty-6.1.26
2014-08-13 21:44:00,528 INFO org.mortbay.log: Extract jar:file:/usr/local/hadoop-2.4.0/share/hadoop/yarn/hadoop-yarn-common-2.4.0.jar!/webapps/cluster to /tmp/Jetty_0_0_0_0_8088_cluster____u0rgz3/webapp
2014-08-13 21:44:00,730 INFO org.mortbay.log: Started SelectChannelConnector@0.0.0.0:8088
2014-08-13 21:44:00,730 INFO org.apache.hadoop.yarn.webapp.WebApps: Web app /cluster started at 8088
2014-08-13 21:44:01,062 INFO org.apache.hadoop.yarn.webapp.WebApps: Registered webapp guice modules
2014-08-13 21:44:01,082 INFO org.apache.hadoop.ipc.CallQueueManager: Using callQueue class java.util.concurrent.LinkedBlockingQueue
2014-08-13 21:44:01,082 INFO org.apache.hadoop.ipc.Server: Starting Socket Reader #1 for port 8033
2014-08-13 21:44:01,085 INFO org.apache.hadoop.yarn.factories.impl.pb.RpcServerFactoryPBImpl: Adding protocol org.apache.hadoop.yarn.server.api.ResourceManagerAdministrationProtocolPB to the server
2014-08-13 21:44:01,085 INFO org.apache.hadoop.ipc.Server: IPC Server Responder: starting
2014-08-13 21:44:01,085 INFO org.apache.hadoop.ipc.Server: IPC Server listener on 8033: starting
2014-08-13 21:46:03,137 INFO org.apache.hadoop.yarn.util.RackResolver: Resolved rticdev.igatecorp.com to /default-rack
2014-08-13 21:46:03,143 INFO org.apache.hadoop.yarn.server.resourcemanager.ResourceTrackerService: NodeManager from node rticdev.igatecorp.com(cmPort: 56794 httpPort: 8042) registered with capability: <memory:8192, vCores:8>, assigned nodeId rticdev.igatecorp.com:56794
2014-08-13 21:46:03,144 INFO org.apache.hadoop.yarn.server.resourcemanager.rmnode.RMNodeImpl: rticdev.igatecorp.com:56794 Node Transitioned from NEW to RUNNING
2014-08-13 21:46:03,145 INFO org.apache.hadoop.yarn.server.resourcemanager.scheduler.capacity.CapacityScheduler: Added node rticdev.igatecorp.com:56794 clusterResource: <memory:8192, vCores:8>
2014-08-13 21:48:05,841 INFO org.apache.hadoop.yarn.server.resourcemanager.ClientRMService: Allocated new applicationId: 1
2014-08-13 21:48:07,626 INFO org.apache.hadoop.yarn.server.resourcemanager.ClientRMService: Application with id 1 submitted by user hduser
2014-08-13 21:48:07,626 INFO org.apache.hadoop.yarn.server.resourcemanager.rmapp.RMAppImpl: Storing application with id application_1407946440243_0001
2014-08-13 21:48:07,627 INFO org.apache.hadoop.yarn.server.resourcemanager.RMAuditLogger: USER=hduser	IP=172.16.1.31	OPERATION=Submit Application Request	TARGET=ClientRMService	RESULT=SUCCESS	APPID=application_1407946440243_0001
2014-08-13 21:48:07,627 INFO org.apache.hadoop.yarn.server.resourcemanager.rmapp.RMAppImpl: application_1407946440243_0001 State change from NEW to NEW_SAVING
2014-08-13 21:48:07,632 INFO org.apache.hadoop.yarn.server.resourcemanager.recovery.RMStateStore: Storing info for app: application_1407946440243_0001
2014-08-13 21:48:07,633 INFO org.apache.hadoop.yarn.server.resourcemanager.rmapp.RMAppImpl: application_1407946440243_0001 State change from NEW_SAVING to SUBMITTED
2014-08-13 21:48:07,634 INFO org.apache.hadoop.yarn.server.resourcemanager.scheduler.capacity.ParentQueue: Application added - appId: application_1407946440243_0001 user: hduser leaf-queue of parent: root #applications: 1
2014-08-13 21:48:07,635 INFO org.apache.hadoop.yarn.server.resourcemanager.scheduler.capacity.CapacityScheduler: Accepted application application_1407946440243_0001 from user: hduser, in queue: default
2014-08-13 21:48:07,643 INFO org.apache.hadoop.yarn.server.resourcemanager.rmapp.RMAppImpl: application_1407946440243_0001 State change from SUBMITTED to ACCEPTED
2014-08-13 21:48:07,643 INFO org.apache.hadoop.yarn.server.resourcemanager.ApplicationMasterService: Registering app attempt : appattempt_1407946440243_0001_000001
2014-08-13 21:48:07,665 INFO org.apache.hadoop.yarn.server.resourcemanager.rmapp.attempt.RMAppAttemptImpl: appattempt_1407946440243_0001_000001 State change from NEW to SUBMITTED
2014-08-13 21:48:07,679 INFO org.apache.hadoop.yarn.server.resourcemanager.scheduler.capacity.LeafQueue: Application application_1407946440243_0001 from user: hduser activated in queue: default
2014-08-13 21:48:07,679 INFO org.apache.hadoop.yarn.server.resourcemanager.scheduler.capacity.LeafQueue: Application added - appId: application_1407946440243_0001 user: org.apache.hadoop.yarn.server.resourcemanager.scheduler.capacity.LeafQueue$User@66ae2a84, leaf-queue: default #user-pending-applications: 0 #user-active-applications: 1 #queue-pending-applications: 0 #queue-active-applications: 1
2014-08-13 21:48:07,679 INFO org.apache.hadoop.yarn.server.resourcemanager.scheduler.capacity.CapacityScheduler: Added Application Attempt appattempt_1407946440243_0001_000001 to scheduler from user hduser in queue default
2014-08-13 21:48:07,681 INFO org.apache.hadoop.yarn.server.resourcemanager.rmapp.attempt.RMAppAttemptImpl: appattempt_1407946440243_0001_000001 State change from SUBMITTED to SCHEDULED
2014-08-13 21:48:08,460 INFO org.apache.hadoop.yarn.server.resourcemanager.rmcontainer.RMContainerImpl: container_1407946440243_0001_01_000001 Container Transitioned from NEW to ALLOCATED
2014-08-13 21:48:08,460 INFO org.apache.hadoop.yarn.server.resourcemanager.RMAuditLogger: USER=hduser	OPERATION=AM Allocated Container	TARGET=SchedulerApp	RESULT=SUCCESS	APPID=application_1407946440243_0001	CONTAINERID=container_1407946440243_0001_01_000001
2014-08-13 21:48:08,460 INFO org.apache.hadoop.yarn.server.resourcemanager.scheduler.common.fica.FiCaSchedulerNode: Assigned container container_1407946440243_0001_01_000001 of capacity <memory:2048, vCores:1> on host rticdev.igatecorp.com:56794, which currently has 1 containers, <memory:2048, vCores:1> used and <memory:6144, vCores:7> available
2014-08-13 21:48:08,460 INFO org.apache.hadoop.yarn.server.resourcemanager.scheduler.capacity.LeafQueue: assignedContainer application=application_1407946440243_0001 container=Container: [ContainerId: container_1407946440243_0001_01_000001, NodeId: rticdev.igatecorp.com:56794, NodeHttpAddress: rticdev.igatecorp.com:8042, Resource: <memory:2048, vCores:1>, Priority: 0, Token: null, ] containerId=container_1407946440243_0001_01_000001 queue=default: capacity=1.0, absoluteCapacity=1.0, usedResources=<memory:0, vCores:0>usedCapacity=0.0, absoluteUsedCapacity=0.0, numApps=1, numContainers=0 usedCapacity=0.0 absoluteUsedCapacity=0.0 used=<memory:0, vCores:0> cluster=<memory:8192, vCores:8>
2014-08-13 21:48:08,461 INFO org.apache.hadoop.yarn.server.resourcemanager.scheduler.capacity.ParentQueue: Re-sorting assigned queue: root.default stats: default: capacity=1.0, absoluteCapacity=1.0, usedResources=<memory:2048, vCores:1>usedCapacity=0.25, absoluteUsedCapacity=0.25, numApps=1, numContainers=1
2014-08-13 21:48:08,461 INFO org.apache.hadoop.yarn.server.resourcemanager.scheduler.capacity.ParentQueue: assignedContainer queue=root usedCapacity=0.25 absoluteUsedCapacity=0.25 used=<memory:2048, vCores:1> cluster=<memory:8192, vCores:8>
2014-08-13 21:48:08,462 INFO org.apache.hadoop.yarn.server.resourcemanager.security.NMTokenSecretManagerInRM: Sending NMToken for nodeId : rticdev.igatecorp.com:56794 for container : container_1407946440243_0001_01_000001
2014-08-13 21:48:08,468 INFO org.apache.hadoop.yarn.server.resourcemanager.rmcontainer.RMContainerImpl: container_1407946440243_0001_01_000001 Container Transitioned from ALLOCATED to ACQUIRED
2014-08-13 21:48:08,468 INFO org.apache.hadoop.yarn.server.resourcemanager.security.NMTokenSecretManagerInRM: Clear node set for appattempt_1407946440243_0001_000001
2014-08-13 21:48:08,471 INFO org.apache.hadoop.yarn.server.resourcemanager.rmapp.attempt.RMAppAttemptImpl: Storing attempt: AppId: application_1407946440243_0001 AttemptId: appattempt_1407946440243_0001_000001 MasterContainer: Container: [ContainerId: container_1407946440243_0001_01_000001, NodeId: rticdev.igatecorp.com:56794, NodeHttpAddress: rticdev.igatecorp.com:8042, Resource: <memory:2048, vCores:1>, Priority: 0, Token: Token { kind: ContainerToken, service: 172.16.1.31:56794 }, ]
2014-08-13 21:48:08,475 INFO org.apache.hadoop.yarn.server.resourcemanager.rmapp.attempt.RMAppAttemptImpl: appattempt_1407946440243_0001_000001 State change from SCHEDULED to ALLOCATED_SAVING
2014-08-13 21:48:08,487 INFO org.apache.hadoop.yarn.server.resourcemanager.rmapp.attempt.RMAppAttemptImpl: appattempt_1407946440243_0001_000001 State change from ALLOCATED_SAVING to ALLOCATED
2014-08-13 21:48:08,491 INFO org.apache.hadoop.yarn.server.resourcemanager.amlauncher.AMLauncher: Launching masterappattempt_1407946440243_0001_000001
2014-08-13 21:48:08,519 INFO org.apache.hadoop.yarn.server.resourcemanager.amlauncher.AMLauncher: Setting up container Container: [ContainerId: container_1407946440243_0001_01_000001, NodeId: rticdev.igatecorp.com:56794, NodeHttpAddress: rticdev.igatecorp.com:8042, Resource: <memory:2048, vCores:1>, Priority: 0, Token: Token { kind: ContainerToken, service: 172.16.1.31:56794 }, ] for AM appattempt_1407946440243_0001_000001
2014-08-13 21:48:08,519 INFO org.apache.hadoop.yarn.server.resourcemanager.amlauncher.AMLauncher: Command to launch container container_1407946440243_0001_01_000001 : $JAVA_HOME/bin/java -Dlog4j.configuration=container-log4j.properties -Dyarn.app.container.log.dir=<LOG_DIR> -Dyarn.app.container.log.filesize=0 -Dhadoop.root.logger=INFO,CLA  -Xmx1024m org.apache.hadoop.mapreduce.v2.app.MRAppMaster 1><LOG_DIR>/stdout 2><LOG_DIR>/stderr 
2014-08-13 21:48:08,737 INFO org.apache.hadoop.yarn.server.resourcemanager.amlauncher.AMLauncher: Done launching container Container: [ContainerId: container_1407946440243_0001_01_000001, NodeId: rticdev.igatecorp.com:56794, NodeHttpAddress: rticdev.igatecorp.com:8042, Resource: <memory:2048, vCores:1>, Priority: 0, Token: Token { kind: ContainerToken, service: 172.16.1.31:56794 }, ] for AM appattempt_1407946440243_0001_000001
2014-08-13 21:48:08,738 INFO org.apache.hadoop.yarn.server.resourcemanager.rmapp.attempt.RMAppAttemptImpl: appattempt_1407946440243_0001_000001 State change from ALLOCATED to LAUNCHED
2014-08-13 21:48:09,453 INFO org.apache.hadoop.yarn.server.resourcemanager.rmcontainer.RMContainerImpl: container_1407946440243_0001_01_000001 Container Transitioned from ACQUIRED to RUNNING
2014-08-13 21:48:12,619 INFO SecurityLogger.org.apache.hadoop.ipc.Server: Auth successful for appattempt_1407946440243_0001_000001 (auth:SIMPLE)
2014-08-13 21:48:12,625 INFO org.apache.hadoop.yarn.server.resourcemanager.ApplicationMasterService: AM registration appattempt_1407946440243_0001_000001
2014-08-13 21:48:12,626 INFO org.apache.hadoop.yarn.server.resourcemanager.RMAuditLogger: USER=hduser	IP=172.16.1.31	OPERATION=Register App Master	TARGET=ApplicationMasterService	RESULT=SUCCESS	APPID=application_1407946440243_0001	APPATTEMPTID=appattempt_1407946440243_0001_000001
2014-08-13 21:48:12,626 INFO org.apache.hadoop.yarn.server.resourcemanager.rmapp.attempt.RMAppAttemptImpl: appattempt_1407946440243_0001_000001 State change from LAUNCHED to RUNNING
2014-08-13 21:48:12,626 INFO org.apache.hadoop.yarn.server.resourcemanager.rmapp.RMAppImpl: application_1407946440243_0001 State change from ACCEPTED to RUNNING
2014-08-13 21:48:14,464 INFO org.apache.hadoop.yarn.server.resourcemanager.rmcontainer.RMContainerImpl: container_1407946440243_0001_01_000002 Container Transitioned from NEW to ALLOCATED
2014-08-13 21:48:14,465 INFO org.apache.hadoop.yarn.server.resourcemanager.RMAuditLogger: USER=hduser	OPERATION=AM Allocated Container	TARGET=SchedulerApp	RESULT=SUCCESS	APPID=application_1407946440243_0001	CONTAINERID=container_1407946440243_0001_01_000002
2014-08-13 21:48:14,465 INFO org.apache.hadoop.yarn.server.resourcemanager.scheduler.common.fica.FiCaSchedulerNode: Assigned container container_1407946440243_0001_01_000002 of capacity <memory:1024, vCores:1> on host rticdev.igatecorp.com:56794, which currently has 2 containers, <memory:3072, vCores:2> used and <memory:5120, vCores:6> available
2014-08-13 21:48:14,465 INFO org.apache.hadoop.yarn.server.resourcemanager.scheduler.capacity.LeafQueue: assignedContainer application=application_1407946440243_0001 container=Container: [ContainerId: container_1407946440243_0001_01_000002, NodeId: rticdev.igatecorp.com:56794, NodeHttpAddress: rticdev.igatecorp.com:8042, Resource: <memory:1024, vCores:1>, Priority: 20, Token: null, ] containerId=container_1407946440243_0001_01_000002 queue=default: capacity=1.0, absoluteCapacity=1.0, usedResources=<memory:2048, vCores:1>usedCapacity=0.25, absoluteUsedCapacity=0.25, numApps=1, numContainers=1 usedCapacity=0.25 absoluteUsedCapacity=0.25 used=<memory:2048, vCores:1> cluster=<memory:8192, vCores:8>
2014-08-13 21:48:14,465 INFO org.apache.hadoop.yarn.server.resourcemanager.scheduler.capacity.ParentQueue: Re-sorting assigned queue: root.default stats: default: capacity=1.0, absoluteCapacity=1.0, usedResources=<memory:3072, vCores:2>usedCapacity=0.375, absoluteUsedCapacity=0.375, numApps=1, numContainers=2
2014-08-13 21:48:14,465 INFO org.apache.hadoop.yarn.server.resourcemanager.scheduler.capacity.ParentQueue: assignedContainer queue=root usedCapacity=0.375 absoluteUsedCapacity=0.375 used=<memory:3072, vCores:2> cluster=<memory:8192, vCores:8>
2014-08-13 21:48:14,690 INFO org.apache.hadoop.yarn.server.resourcemanager.security.NMTokenSecretManagerInRM: Sending NMToken for nodeId : rticdev.igatecorp.com:56794 for container : container_1407946440243_0001_01_000002
2014-08-13 21:48:14,690 INFO org.apache.hadoop.yarn.server.resourcemanager.rmcontainer.RMContainerImpl: container_1407946440243_0001_01_000002 Container Transitioned from ALLOCATED to ACQUIRED
2014-08-13 21:48:15,466 INFO org.apache.hadoop.yarn.server.resourcemanager.rmcontainer.RMContainerImpl: container_1407946440243_0001_01_000002 Container Transitioned from ACQUIRED to RUNNING
2014-08-13 21:48:15,700 INFO org.apache.hadoop.yarn.server.resourcemanager.scheduler.AppSchedulingInfo: checking for deactivate... 
2014-08-13 21:48:18,183 INFO org.apache.hadoop.yarn.server.resourcemanager.rmapp.attempt.RMAppAttemptImpl: Updating application attempt appattempt_1407946440243_0001_000001 with final state: FINISHING
2014-08-13 21:48:18,184 INFO org.apache.hadoop.yarn.server.resourcemanager.rmapp.attempt.RMAppAttemptImpl: appattempt_1407946440243_0001_000001 State change from RUNNING to FINAL_SAVING
2014-08-13 21:48:18,184 INFO org.apache.hadoop.yarn.server.resourcemanager.rmapp.RMAppImpl: Updating application application_1407946440243_0001 with final state: FINISHING
2014-08-13 21:48:18,184 INFO org.apache.hadoop.yarn.server.resourcemanager.rmapp.RMAppImpl: application_1407946440243_0001 State change from RUNNING to FINAL_SAVING
2014-08-13 21:48:18,184 INFO org.apache.hadoop.yarn.server.resourcemanager.recovery.RMStateStore: Storing info for app: application_1407946440243_0001
2014-08-13 21:48:18,185 INFO org.apache.hadoop.yarn.server.resourcemanager.rmapp.attempt.RMAppAttemptImpl: appattempt_1407946440243_0001_000001 State change from FINAL_SAVING to FINISHING
2014-08-13 21:48:18,185 INFO org.apache.hadoop.yarn.server.resourcemanager.rmapp.RMAppImpl: application_1407946440243_0001 State change from FINAL_SAVING to FINISHING
2014-08-13 21:48:18,338 INFO org.apache.hadoop.yarn.server.resourcemanager.rmcontainer.RMContainerImpl: container_1407946440243_0001_01_000002 Container Transitioned from RUNNING to COMPLETED
2014-08-13 21:48:18,338 INFO org.apache.hadoop.yarn.server.resourcemanager.scheduler.common.fica.FiCaSchedulerApp: Completed container: container_1407946440243_0001_01_000002 in state: COMPLETED event:FINISHED
2014-08-13 21:48:18,338 INFO org.apache.hadoop.yarn.server.resourcemanager.RMAuditLogger: USER=hduser	OPERATION=AM Released Container	TARGET=SchedulerApp	RESULT=SUCCESS	APPID=application_1407946440243_0001	CONTAINERID=container_1407946440243_0001_01_000002
2014-08-13 21:48:18,338 INFO org.apache.hadoop.yarn.server.resourcemanager.scheduler.common.fica.FiCaSchedulerNode: Released container container_1407946440243_0001_01_000002 of capacity <memory:1024, vCores:1> on host rticdev.igatecorp.com:56794, which currently has 1 containers, <memory:2048, vCores:1> used and <memory:6144, vCores:7> available, release resources=true
2014-08-13 21:48:18,338 INFO org.apache.hadoop.yarn.server.resourcemanager.scheduler.capacity.LeafQueue: default used=<memory:2048, vCores:1> numContainers=1 user=hduser user-resources=<memory:2048, vCores:1>
2014-08-13 21:48:18,338 INFO org.apache.hadoop.yarn.server.resourcemanager.scheduler.capacity.LeafQueue: completedContainer container=Container: [ContainerId: container_1407946440243_0001_01_000002, NodeId: rticdev.igatecorp.com:56794, NodeHttpAddress: rticdev.igatecorp.com:8042, Resource: <memory:1024, vCores:1>, Priority: 20, Token: Token { kind: ContainerToken, service: 172.16.1.31:56794 }, ] resource=<memory:1024, vCores:1> queue=default: capacity=1.0, absoluteCapacity=1.0, usedResources=<memory:2048, vCores:1>usedCapacity=0.25, absoluteUsedCapacity=0.25, numApps=1, numContainers=1 usedCapacity=0.25 absoluteUsedCapacity=0.25 used=<memory:2048, vCores:1> cluster=<memory:8192, vCores:8>
2014-08-13 21:48:18,338 INFO org.apache.hadoop.yarn.server.resourcemanager.scheduler.capacity.ParentQueue: completedContainer queue=root usedCapacity=0.25 absoluteUsedCapacity=0.25 used=<memory:2048, vCores:1> cluster=<memory:8192, vCores:8>
2014-08-13 21:48:18,338 INFO org.apache.hadoop.yarn.server.resourcemanager.scheduler.capacity.ParentQueue: Re-sorting completed queue: root.default stats: default: capacity=1.0, absoluteCapacity=1.0, usedResources=<memory:2048, vCores:1>usedCapacity=0.25, absoluteUsedCapacity=0.25, numApps=1, numContainers=1
2014-08-13 21:48:18,338 INFO org.apache.hadoop.yarn.server.resourcemanager.scheduler.capacity.CapacityScheduler: Application attempt appattempt_1407946440243_0001_000001 released container container_1407946440243_0001_01_000002 on node: host: rticdev.igatecorp.com:56794 #containers=1 available=6144 used=2048 with event: FINISHED
2014-08-13 21:48:25,351 INFO org.apache.hadoop.yarn.server.resourcemanager.rmcontainer.RMContainerImpl: container_1407946440243_0001_01_000001 Container Transitioned from RUNNING to COMPLETED
2014-08-13 21:48:25,351 INFO org.apache.hadoop.yarn.server.resourcemanager.ApplicationMasterService: Unregistering app attempt : appattempt_1407946440243_0001_000001
2014-08-13 21:48:25,351 INFO org.apache.hadoop.yarn.server.resourcemanager.scheduler.common.fica.FiCaSchedulerApp: Completed container: container_1407946440243_0001_01_000001 in state: COMPLETED event:FINISHED
2014-08-13 21:48:25,352 INFO org.apache.hadoop.yarn.server.resourcemanager.RMAuditLogger: USER=hduser	OPERATION=AM Released Container	TARGET=SchedulerApp	RESULT=SUCCESS	APPID=application_1407946440243_0001	CONTAINERID=container_1407946440243_0001_01_000001
2014-08-13 21:48:25,352 INFO org.apache.hadoop.yarn.server.resourcemanager.scheduler.common.fica.FiCaSchedulerNode: Released container container_1407946440243_0001_01_000001 of capacity <memory:2048, vCores:1> on host rticdev.igatecorp.com:56794, which currently has 0 containers, <memory:0, vCores:0> used and <memory:8192, vCores:8> available, release resources=true
2014-08-13 21:48:25,352 INFO org.apache.hadoop.yarn.server.resourcemanager.scheduler.capacity.LeafQueue: default used=<memory:0, vCores:0> numContainers=0 user=hduser user-resources=<memory:0, vCores:0>
2014-08-13 21:48:25,352 INFO org.apache.hadoop.yarn.server.resourcemanager.scheduler.capacity.LeafQueue: completedContainer container=Container: [ContainerId: container_1407946440243_0001_01_000001, NodeId: rticdev.igatecorp.com:56794, NodeHttpAddress: rticdev.igatecorp.com:8042, Resource: <memory:2048, vCores:1>, Priority: 0, Token: Token { kind: ContainerToken, service: 172.16.1.31:56794 }, ] resource=<memory:2048, vCores:1> queue=default: capacity=1.0, absoluteCapacity=1.0, usedResources=<memory:0, vCores:0>usedCapacity=0.0, absoluteUsedCapacity=0.0, numApps=1, numContainers=0 usedCapacity=0.0 absoluteUsedCapacity=0.0 used=<memory:0, vCores:0> cluster=<memory:8192, vCores:8>
2014-08-13 21:48:25,352 INFO org.apache.hadoop.yarn.server.resourcemanager.scheduler.capacity.ParentQueue: completedContainer queue=root usedCapacity=0.0 absoluteUsedCapacity=0.0 used=<memory:0, vCores:0> cluster=<memory:8192, vCores:8>
2014-08-13 21:48:25,352 INFO org.apache.hadoop.yarn.server.resourcemanager.scheduler.capacity.ParentQueue: Re-sorting completed queue: root.default stats: default: capacity=1.0, absoluteCapacity=1.0, usedResources=<memory:0, vCores:0>usedCapacity=0.0, absoluteUsedCapacity=0.0, numApps=1, numContainers=0
2014-08-13 21:48:25,353 INFO org.apache.hadoop.yarn.server.resourcemanager.scheduler.capacity.CapacityScheduler: Application attempt appattempt_1407946440243_0001_000001 released container container_1407946440243_0001_01_000001 on node: host: rticdev.igatecorp.com:56794 #containers=0 available=8192 used=0 with event: FINISHED
2014-08-13 21:48:25,353 INFO org.apache.hadoop.yarn.server.resourcemanager.rmapp.attempt.RMAppAttemptImpl: appattempt_1407946440243_0001_000001 State change from FINISHING to FINISHED
2014-08-13 21:48:25,355 INFO org.apache.hadoop.yarn.server.resourcemanager.rmapp.RMAppImpl: application_1407946440243_0001 State change from FINISHING to FINISHED
2014-08-13 21:48:25,355 INFO org.apache.hadoop.yarn.server.resourcemanager.scheduler.capacity.CapacityScheduler: Application Attempt appattempt_1407946440243_0001_000001 is done. finalState=FINISHED
2014-08-13 21:48:25,356 INFO org.apache.hadoop.yarn.server.resourcemanager.scheduler.AppSchedulingInfo: Application application_1407946440243_0001 requests cleared
2014-08-13 21:48:25,356 INFO org.apache.hadoop.yarn.server.resourcemanager.scheduler.capacity.LeafQueue: Application removed - appId: application_1407946440243_0001 user: hduser queue: default #user-pending-applications: 0 #user-active-applications: 0 #queue-pending-applications: 0 #queue-active-applications: 0
2014-08-13 21:48:25,356 INFO org.apache.hadoop.yarn.server.resourcemanager.scheduler.capacity.ParentQueue: Application removed - appId: application_1407946440243_0001 user: hduser leaf-queue of parent: root #applications: 0
2014-08-13 21:48:25,356 INFO org.apache.hadoop.yarn.server.resourcemanager.amlauncher.AMLauncher: Cleaning master appattempt_1407946440243_0001_000001
2014-08-13 21:48:25,357 INFO org.apache.hadoop.yarn.server.resourcemanager.RMAuditLogger: USER=hduser	OPERATION=Application Finished - Succeeded	TARGET=RMAppManager	RESULT=SUCCESS	APPID=application_1407946440243_0001
2014-08-13 21:48:25,359 INFO org.apache.hadoop.yarn.server.resourcemanager.RMAppManager$ApplicationSummary: appId=application_1407946440243_0001,name=PigLatin:passwd.pig,user=hduser,queue=default,state=FINISHED,trackingUrl=http://rticdev.igatecorp.com:8088/proxy/application_1407946440243_0001/jobhistory/job/job_1407946440243_0001,appMasterHost=rticdev.igatecorp.com,startTime=1407946687625,finishTime=1407946698184,finalStatus=SUCCEEDED
2014-08-14 15:01:37,832 ERROR org.apache.hadoop.yarn.server.resourcemanager.ResourceManager: RECEIVED SIGNAL 15: SIGTERM
2014-08-14 15:01:37,836 INFO org.mortbay.log: Stopped SelectChannelConnector@0.0.0.0:8088
2014-08-14 15:01:37,936 INFO org.apache.hadoop.ipc.Server: Stopping server on 8032
2014-08-14 15:01:37,937 INFO org.apache.hadoop.ipc.Server: Stopping IPC Server listener on 8032
2014-08-14 15:01:37,937 INFO org.apache.hadoop.ipc.Server: Stopping server on 8033
2014-08-14 15:01:37,937 INFO org.apache.hadoop.ipc.Server: Stopping IPC Server Responder
2014-08-14 15:01:37,937 INFO org.apache.hadoop.ipc.Server: Stopping IPC Server listener on 8033
2014-08-14 15:01:37,938 INFO org.apache.hadoop.ipc.Server: Stopping IPC Server Responder
2014-08-14 15:01:37,938 INFO org.apache.hadoop.yarn.server.resourcemanager.ResourceManager: Transitioning to standby state
2014-08-14 15:01:37,938 INFO org.apache.hadoop.metrics2.impl.MetricsSystemImpl: Stopping ResourceManager metrics system...
2014-08-14 15:01:37,939 INFO org.apache.hadoop.metrics2.impl.MetricsSystemImpl: ResourceManager metrics system stopped.
2014-08-14 15:01:37,940 INFO org.apache.hadoop.metrics2.impl.MetricsSystemImpl: ResourceManager metrics system shutdown complete.
2014-08-14 15:01:37,940 INFO org.apache.hadoop.yarn.event.AsyncDispatcher: AsyncDispatcher is draining to stop, igonring any new events.
2014-08-14 15:01:37,940 WARN org.apache.hadoop.yarn.server.resourcemanager.amlauncher.ApplicationMasterLauncher: org.apache.hadoop.yarn.server.resourcemanager.amlauncher.ApplicationMasterLauncher$LauncherThread interrupted. Returning.
2014-08-14 15:01:37,940 INFO org.apache.hadoop.ipc.Server: Stopping server on 8030
2014-08-14 15:01:37,941 INFO org.apache.hadoop.ipc.Server: Stopping IPC Server listener on 8030
2014-08-14 15:01:37,941 INFO org.apache.hadoop.ipc.Server: Stopping IPC Server Responder
2014-08-14 15:01:37,941 INFO org.apache.hadoop.ipc.Server: Stopping server on 8031
2014-08-14 15:01:37,943 INFO org.apache.hadoop.ipc.Server: Stopping IPC Server listener on 8031
2014-08-14 15:01:37,943 INFO org.apache.hadoop.ipc.Server: Stopping IPC Server Responder
2014-08-14 15:01:37,943 ERROR org.apache.hadoop.yarn.server.resourcemanager.ResourceManager: Returning, interrupted : java.lang.InterruptedException
2014-08-14 15:01:37,943 INFO org.apache.hadoop.yarn.event.AsyncDispatcher: AsyncDispatcher is draining to stop, igonring any new events.
2014-08-14 15:01:37,943 INFO org.apache.hadoop.yarn.event.AsyncDispatcher: AsyncDispatcher is draining to stop, igonring any new events.
2014-08-14 15:01:37,944 INFO org.apache.hadoop.yarn.event.AsyncDispatcher: AsyncDispatcher is draining to stop, igonring any new events.
2014-08-14 15:01:37,944 INFO org.apache.hadoop.yarn.event.AsyncDispatcher: AsyncDispatcher is draining to stop, igonring any new events.
2014-08-14 15:01:37,944 INFO org.apache.hadoop.yarn.event.AsyncDispatcher: AsyncDispatcher is draining to stop, igonring any new events.
2014-08-14 15:01:37,944 INFO org.apache.hadoop.yarn.util.AbstractLivelinessMonitor: NMLivelinessMonitor thread interrupted
2014-08-14 15:01:37,944 INFO org.apache.hadoop.yarn.event.AsyncDispatcher: AsyncDispatcher is draining to stop, igonring any new events.
2014-08-14 15:01:37,944 INFO org.apache.hadoop.yarn.event.AsyncDispatcher: AsyncDispatcher is draining to stop, igonring any new events.
2014-08-14 15:01:37,945 INFO org.apache.hadoop.yarn.event.AsyncDispatcher: AsyncDispatcher is draining to stop, igonring any new events.
2014-08-14 15:01:37,945 INFO org.apache.hadoop.yarn.event.AsyncDispatcher: AsyncDispatcher is draining to stop, igonring any new events.
2014-08-14 15:01:37,945 INFO org.apache.hadoop.yarn.event.AsyncDispatcher: AsyncDispatcher is draining to stop, igonring any new events.
2014-08-14 15:01:37,945 INFO org.apache.hadoop.yarn.util.AbstractLivelinessMonitor: AMLivelinessMonitor thread interrupted
2014-08-14 15:01:37,945 INFO org.apache.hadoop.yarn.util.AbstractLivelinessMonitor: org.apache.hadoop.yarn.server.resourcemanager.rmcontainer.ContainerAllocationExpirer thread interrupted
2014-08-14 15:01:37,945 INFO org.apache.hadoop.yarn.util.AbstractLivelinessMonitor: AMLivelinessMonitor thread interrupted
2014-08-14 15:01:37,945 ERROR org.apache.hadoop.security.token.delegation.AbstractDelegationTokenSecretManager: InterruptedExcpetion recieved for ExpiredTokenRemover thread java.lang.InterruptedException: sleep interrupted
2014-08-14 15:01:37,946 INFO org.apache.hadoop.yarn.server.resourcemanager.ResourceManager: Transitioned to standby state
2014-08-14 15:01:37,946 INFO org.apache.hadoop.yarn.server.resourcemanager.ResourceManager: SHUTDOWN_MSG: 
/************************************************************
SHUTDOWN_MSG: Shutting down ResourceManager at rticdev.igatecorp.com/172.16.1.31
************************************************************/
